Workbook

Sheet master
A1: No. | B1: メギド名 | C1: 入手手段 | D1: スタイル | E1: クラス | F1: 攻撃回数(シフト後も含む） | G1: 飛行している | H1: 身長 | I1: 性別 | J1: 年齢 | K1: 誕生日/転生日 | L1: 内部属性
A2: 祖01 | B2: バエル | C2: メイン | D2: バースト | E2: スナイパー | H2: 124 | I2: 男性 | K2: 44937 | L2: 雷
A3: 祖01 | B3: バエルC | C3: 召喚 | D3: カウンター | E3: スナイパー | H3: 124 | I3: 男性 | K3: 44937 | L3: 雷
A4: 祖02 | B4: アガレスC | C4: イベント | D4: カウンター | E4: スナイパー | H4: 186 | I4: 男性 | J4: 26 | K4: 45106 | L4: 地
A5: 祖02 | B5: アガレス | C5: 召喚 | D5: バースト | E5: スナイパー | H5: 186 | I5: 男性 | J5: 26 | K5: 45106 | L5: 地
A6: 祖03 | B6: ウァサゴB | C6: 召喚 | D6: バースト | E6: ファイター | H6: 164 | I6: 女性 | J6: 19 | K6: 45021 | L6: 地
A7: 祖03 | B7: ウァサゴ | C7: 召喚 | D7: ラッシュ | E7: ファイター | H7: 164 | I7: 女性 | J7: 19 | K7: 45021 | L7: 地
A8: 祖04 | B8: ガミジンB | C8: イベント | D8: バースト | E8: ファイター | H8: 185 | I8: 男性 | J8: 28 | K8: 45002 | L8: 地
A9: 祖04 | B9: ガミジン | C9: 召喚 | D9: カウンター | E9: ファイター | H9: 185 | I9: 男性 | J9: 28 | K9: 45002 | L9: 地
A10: 祖05 | B10: マルバスR | C10: イベント | D10: ラッシュ | E10: スナイパー | H10: 145 | I10: 女性 | J10: 14 | K10: 45031 | L10: 地
A11: 祖05 | B11: マルバス | C11: 召喚 | D11: カウンター | E11: スナイパー | H11: 145 | I11: 女性 | J11: 14 | K11: 45031 | L11: 地
A12: 祖06 | B12: ウァレフォルC | C12: 召喚 | D12: カウンター | E12: ファイター | H12: 181 | I12: 女性 | J12: 25 | K12: 45005 | L12: 雷
A13: 祖06 | B13: ウァレフォル | C13: 召喚 | D13: ラッシュ | E13: ファイター | F13: 2 | H13: 181 | I13: 女性 | J13: 25 | K13: 45005 | L13: 地
A14: 祖07 | B14: アモンR | C14: 召喚 | D14: ラッシュ | E14: ファイター | F14: 3 | H14: 153 | I14: 男性 | J14: 13 | K14: 45157 | L14: 火
A15: 祖07 | B15: アモン | C15: 召喚 | D15: バースト | E15: ファイター | H15: 153 | I15: 男性 | J15: 13 | K15: 45157 | L15: 火
A16: 祖08 | B16: バルバトスR | C16: 召喚 | D16: ラッシュ | E16: スナイパー | H16: 173 | I16: 男性 | K16: 45086 | L16: 風
A17: 祖08 | B17: バルバトス | C17: メイン | D17: カウンター | E17: スナイパー | H17: 173 | I17: 男性 | K17: 45086 | L17: 風
A18: 祖09 | B18: パイモンB | C18: 召喚 | D18: バースト | E18: ファイター | H18: 179 | I18: 男性 | K18: 45188 | L18: 水
A19: 祖09 | B19: パイモン | C19: メイン | D19: ラッシュ | E19: ファイター | H19: 179 | I19: 男性 | K19: 45188 | L19: 水
A20: 祖10 | B20: ブエルR | C20: 召喚 | D20: ラッシュ | E20: スナイパー | H20: 148 | I20: 女性 | J20: 14 | K20: 44944 | L20: 水
A21: 祖10 | B21: ブエル | C21: 召喚 | D21: バースト | E21: スナイパー | H21: 148 | I21: 女性 | J21: 14 | K21: 44944 | L21: 水
A22: 祖11 | B22: グシオンB | C22: イベント | D22: バースト | E22: スナイパー | H22: 140 | I22: 女性 | J22: 12 | K22: 45173 | L22: 雷
A23: 祖11 | B23: グシオン | C23: 召喚 | D23: カウンター | E23: スナイパー | H23: 140 | I23: 女性 | J23: 12 | K23: 45173 | L23: 雷
A24: 祖12 | B24: シトリーR | C24: イベント | D24: ラッシュ | E24: トルーパー | H24: 165 | I24: 女性 | K24: 44966 | L24: 水
A25: 祖12 | B25: シトリー | C25: 召喚 | D25: カウンター | E25: トルーパー | F25: 2 | H25: 165 | I25: 女性 | K25: 44966 | L25: 雷
A26: 祖13 | B26: ベレトB | C26: 召喚 | D26: バースト | E26: トルーパー | H26: 147 | I26: 女性 | J26: 15 | K26: 44948 | L26: 氷
A27: 祖13 | B27: ベレト | C27: メイン | D27: カウンター | E27: トルーパー | H27: 147 | I27: 女性 | J27: 15 | K27: 44948 | L27: 氷
A28: 祖14 | B28: レラジェR | C28: イベント | D28: ラッシュ | E28: スナイパー | H28: 161 | I28: 女性 | J28: 18 | K28: 45029 | L28: 風
A29: 祖14 | B29: レラジェ | C29: 召喚 | D29: カウンター | E29: スナイパー | H29: 161 | I29: 女性 | J29: 18 | K29: 45029 | L29: 風
A30: 祖15 | B30: エリゴスB | C30: 召喚 | D30: バースト | E30: ファイター | F30: 2 | H30: 163 | I30: 女性 | J30: 25 | K30: 45055 | L30: 火
A31: 祖15 | B31: エリゴス | C31: 召喚 | D31: ラッシュ | E31: ファイター | F31: 2 | H31: 163 | I31: 女性 | J31: 25 | K31: 45055 | L31: 雷
A32: 祖16 | B32: ゼパルC | C32: 召喚 | D32: カウンター | E32: ファイター | H32: 153 | I32: 女性 | J32: 15 | K32: 45052 | L32: 火
A33: 祖16 | B33: ゼパル | C33: 召喚 | D33: ラッシュ | E33: ファイター | H33: 153 | I33: 女性 | J33: 15 | K33: 45052 | L33: 火
A34: 祖17 | B34: ボティスR | C34: イベント | D34: ラッシュ | E34: トルーパー | H34: 167 | I34: 女性 | J34: 24 | K34: 45280 | L34: 雷
A35: 祖17 | B35: ボティス | C35: 召喚 | D35: カウンター | E35: トルーパー | H35: 167 | I35: 女性 | J35: 24 | K35: 45280 | L35: 雷
A36: 祖18 | B36: バティンB | C36: 召喚 | D36: バースト | E36: トルーパー | H36: 163 | I36: 女性 | J36: 23 | K36: 44935 | L36: 火
A37: 祖18 | B37: バティン | C37: 召喚 | D37: ラッシュ | E37: トルーパー | H37: 163 | I37: 女性 | J37: 23 | K37: 44935 | L37: 火
A38: 祖19 | B38: サレオスC | C38: 召喚 | D38: カウンター | E38: ファイター | H38: 165 | I38: 男性 | J38: 25 | K38: 45116 | L38: 水
A39: 祖19 | B39: サレオス | C39: 召喚 | D39: バースト | E39: ファイター | H39: 165 | I39: 男性 | J39: 25 | K39: 45116 | L39: 水
A40: 祖20 | B40: プルソンB | C40: メイン | D40: バースト | E40: トルーパー | H40: 166 | I40: 男性 | J40: 16 | K40: 45039 | L40: 地
...

Sheet Sheet1
A1: No. | B1: メギド名 | C1: 入手手段 | D1: スタイル | E1: クラス | F1: ゲージ | G1: HP | H1: 攻撃力 | I1: 防御力 | J1: 素早さ | K1: 攻撃回数 | L1: 飛行している | M1: 性別 | N1: 身長 | O1: 年齢 | P1: 誕生/転生日 | Q1: ヴィータ名 | S1: 以降検索列
A2: 祖01 | B2: バエル | C2: メイン | D2: バースト | E2: スナイパー | F2: 6 | G2: 4570 | H2: 943 | I2: 487 | J2: 689 | K2: 1 | M2: 男性 | N2: 124 | O2: 不明 | P2: 44937 | Q2: コラン | S2: =IFERROR(__xludf.DUMMYFUNCTION("ArrayFormula(REGEXREPLACE(B2:B1000,""[A-Za-z]$"",""""))"),"バエル") -> バエル | T2: {=VLOOKUP($S$2:$S1000,シート1!D1:K165,3,FALSE)} -> 男性 | U2: {=VLOOKUP($S$2:$S1000,シート1!$D$1:$K$165,4,FALSE)} -> 124 | V2: {=VLOOKUP($S$2:$S1000,シート1!$D$1:$K$165,5,FALSE)} -> 不明 | W2: {=VLOOKUP($S$2:$S1000,シート1!$D$1:$K$165,6,FALSE)} -> 44937 | X2: {=VLOOKUP($S$2:$S1000,シート1!$D$2:$K$165,8,FALSE)} -> コラン | Z2: {=VLOOKUP(B2:B273,シート3!A1:E1000,5,FALSE)} -> 雷
A3: 祖01 | B3: バエルC | C3: 召喚 | D3: カウンター | E3: スナイパー | F3: 4 | G3: 7000 | H3: 1103 | I3: 417 | J3: 620 | K3: 1 | M3: 男性 | N3: 124 | O3: 不明 | P3: 44937 | Q3: コラン | S3: =IFERROR(__xludf.DUMMYFUNCTION("""COMPUTED_VALUE"""),"バエル") -> バエル | T3: 男性 | U3: 124 | V3: 不明 | W3: 44937 | X3: コラン | Z3: 雷
A4: 祖02 | B4: アガレスC | C4: イベント | D4: カウンター | E4: スナイパー | F4: 4 | G4: 6106 | H4: 1218 | I4: 394 | J4: 616 | K4: 1 | M4: 男性 | N4: 186 | O4: 26 | P4: 45106 | Q4: 羽ばたく鰐 | S4: =IFERROR(__xludf.DUMMYFUNCTION("""COMPUTED_VALUE"""),"アガレス") -> アガレス | T4: 男性 | U4: 186 | V4: 26 | W4: 45106 | X4: 羽ばたく鰐 | Z4: 地
A5: 祖02 | B5: アガレス | C5: 召喚 | D5: バースト | E5: スナイパー | F5: 5 | G5: 10712 | H5: 971 | I5: 418 | J5: 427 | K5: 1 | M5: 男性 | N5: 186 | O5: 26 | P5: 45106 | Q5: 羽ばたく鰐 | S5: =IFERROR(__xludf.DUMMYFUNCTION("""COMPUTED_VALUE"""),"アガレス") -> アガレス | T5: 男性 | U5: 186 | V5: 26 | W5: 45106 | X5: 羽ばたく鰐 | Z5: 地
A6: 祖03 | B6: ウァサゴB | C6: 召喚 | D6: バースト | E6: ファイター | F6: 4 | G6: 7736 | H6: 935 | I6: 538 | J6: 460 | K6: 1 | M6: 女性 | N6: 164 | O6: 19 | P6: 45021 | Q6: エリザ | S6: =IFERROR(__xludf.DUMMYFUNCTION("""COMPUTED_VALUE"""),"ウァサゴ") -> ウァサゴ | T6: 女性 | U6: 164 | V6: 19 | W6: 45021 | X6: エリザ | Z6: 地
A7: 祖03 | B7: ウァサゴ | C7: 召喚 | D7: ラッシュ | E7: ファイター | F7: 3 | G7: 5743 | H7: 980 | I7: 500 | J7: 614 | K7: 1 | M7: 女性 | N7: 164 | O7: 19 | P7: 45021 | Q7: エリザ | S7: =IFERROR(__xludf.DUMMYFUNCTION("""COMPUTED_VALUE"""),"ウァサゴ") -> ウァサゴ | T7: 女性 | U7: 164 | V7: 19 | W7: 45021 | X7: エリザ | Z7: 地
A8: 祖04 | B8: ガミジンB | C8: イベント | D8: バースト | E8: ファイター | F8: 4 | G8: 8467 | H8: 1070 | I8: 423 | J8: 492 | K8: 1 | M8: 男性 | N8: 185 | O8: 28 | P8: 45002 | Q8: ？ | S8: =IFERROR(__xludf.DUMMYFUNCTION("""COMPUTED_VALUE"""),"ガミジン") -> ガミジン | T8: 男性 | U8: 185 | V8: 28 | W8: 45002 | X8: ？ | Z8: 地
A9: 祖04 | B9: ガミジン | C9: 召喚 | D9: カウンター | E9: ファイター | F9: 5 | G9: 8729 | H9: 1193 | I9: 418 | J9: 417 | K9: 1 | M9: 男性 | N9: 185 | O9: 28 | P9: 45002 | Q9: ？ | S9: =IFERROR(__xludf.DUMMYFUNCTION("""COMPUTED_VALUE"""),"ガミジン") -> ガミジン | T9: 男性 | U9: 185 | V9: 28 | W9: 45002 | X9: ？ | Z9: 地
A10: 祖05 | B10: マルバスR | C10: イベント | D10: ラッシュ | E10: スナイパー | F10: 4 | G10: 7730 | H10: 597 | I10: 586 | J10: 657 | K10: 1 | M10: 女性 | N10: 145 | O10: 14 | P10: 45031 | Q10: ？ | S10: =IFERROR(__xludf.DUMMYFUNCTION("""COMPUTED_VALUE"""),"マルバス") -> マルバス | T10: 女性 | U10: 145 | V10: 14 | W10: 45031 | X10: ？ | Z10: 地
A11: 祖05 | B11: マルバス | C11: 召喚 | D11: カウンター | E11: スナイパー | F11: 4 | G11: 7262 | H11: 628 | I11: 489 | J11: 719 | K11: 1 | M11: 女性 | N11: 145 | O11: 14 | P11: 45031 | Q11: ？ | S11: =IFERROR(__xludf.DUMMYFUNCTION("""COMPUTED_VALUE"""),"マルバス") -> マルバス | T11: 女性 | U11: 145 | V11: 14 | W11: 45031 | X11: ？ | Z11: 地
A12: 祖06 | B12: ウァレフォルC | C12: 召喚 | D12: カウンター | E12: ファイター | F12: 4 | G12: 6806 | H12: 1340 | I12: 390 | J12: 509 | K12: 1 | M12: 女性 | N12: 181 | O12: 25 | P12: 45005 | Q12: ？ | S12: =IFERROR(__xludf.DUMMYFUNCTION("""COMPUTED_VALUE"""),"ウァレフォル") -> ウァレフォル | T12: 女性 | U12: 181 | V12: 25 | W12: 45005 | X12: ？ | Z12: 雷
A13: 祖06 | B13: ウァレフォル | C13: 召喚 | D13: ラッシュ | E13: ファイター | F13: 3 | G13: 5855 | H13: 1150 | I13: 287 | J13: 678 | K13: 2 | M13: 女性 | N13: 181 | O13: 25 | P13: 45005 | Q13: ？ | S13: =IFERROR(__xludf.DUMMYFUNCTION("""COMPUTED_VALUE"""),"ウァレフォル") -> ウァレフォル | T13: 女性 | U13: 181 | V13: 25 | W13: 45005 | X13: ？ | Z13: 地
A14: 祖07 | B14: アモンR | C14: 召喚 | D14: ラッシュ | E14: ファイター | F14: 2 | G14: 6039 | H14: 1200 | I14: 420 | J14: 627 | K14: 3 | M14: 男性 | N14: 153 | O14: 13 | P14: 45157 | Q14: リュカ | S14: =IFERROR(__xludf.DUMMYFUNCTION("""COMPUTED_VALUE"""),"アモン") -> アモン | T14: 男性 | U14: 153 | V14: 13 | W14: 45157 | X14: リュカ | Z14: 火
A15: 祖07 | B15: アモン | C15: 召喚 | D15: バースト | E15: ファイター | F15: 4 | G15: 4598 | H15: 1194 | I15: 417 | J15: 685 | K15: 1 | M15: 男性 | N15: 153 | O15: 13 | P15: 45157 | Q15: リュカ | S15: =IFERROR(__xludf.DUMMYFUNCTION("""COMPUTED_VALUE"""),"アモン") -> アモン | T15: 男性 | U15: 153 | V15: 13 | W15: 45157 | X15: リュカ | Z15: 火
A16: 祖08 | B16: バルバトスR | C16: 召喚 | D16: ラッシュ | E16: スナイパー | F16: 3 | G16: 7713 | H16: 1226 | I16: 421 | J16: 492 | K16: 1 | M16: 男性 | N16: 173 | O16: 不明 | P16: 45086 | Q16: ？ | S16: =IFERROR(__xludf.DUMMYFUNCTION("""COMPUTED_VALUE"""),"バルバトス") -> バルバトス | T16: 男性 | U16: 173 | V16: 不明 | W16: 45086 | X16: ？ | Z16: 風
A17: 祖08 | B17: バルバトス | C17: メイン | D17: カウンター | E17: スナイパー | F17: 3 | G17: 7659 | H17: 960 | I17: 476 | J17: 474 | K17: 1 | M17: 男性 | N17: 173 | O17: 不明 | P17: 45086 | Q17: ？ | S17: =IFERROR(__xludf.DUMMYFUNCTION("""COMPUTED_VALUE"""),"バルバトス") -> バルバトス | T17: 男性 | U17: 173 | V17: 不明 | W17: 45086 | X17: ？ | Z17: 風
A18: 祖09 | B18: パイモンB | C18: 召喚 | D18: バースト | E18: ファイター | F18: 4 | G18: 7092 | H18: 1194 | I18: 381 | J18: 610 | K18: 1 | M18: 男性 | N18: 179 | O18: 不明 | P18: 45188 | Q18: ？ | S18: =IFERROR(__xludf.DUMMYFUNCTION("""COMPUTED_VALUE"""),"パイモン") -> パイモン | T18: 男性 | U18: 179 | V18: 不明 | W18: 45188 | X18: ？ | Z18: 水
A19: 祖09 | B19: パイモン | C19: メイン | D19: ラッシュ | E19: ファイター | F19: 3 | G19: 7172 | H19: 1191 | I19: 420 | J19: 472 | K19: 1 | M19: 男性 | N19: 179 | O19: 不明 | P19: 45188 | Q19: ？ | S19: =IFERROR(__xludf.DUMMYFUNCTION("""COMPUTED_VALUE"""),"パイモン") -> パイモン | T19: 男性 | U19: 179 | V19: 不明 | W19: 45188 | X19: ？ | Z19: 水
A20: 祖10 | B20: ブエルR | C20: 召喚 | D20: ラッシュ | E20: スナイパー | F20: 2 | G20: 7733 | H20: 640 | I20: 523 | J20: 648 | K20: 1 | M20: 女性 | N20: 148 | O20: 14 | P20: 44944 | Q20: モニカ | S20: =IFERROR(__xludf.DUMMYFUNCTION("""COMPUTED_VALUE"""),"ブエル") -> ブエル | T20: 女性 | U20: 148 | V20: 14 | W20: 44944 | X20: モニカ | Z20: 水
A21: 祖10 | B21: ブエル | C21: 召喚 | D21: バースト | E21: スナイパー | F21: 4 | G21: 7275 | H21: 642 | I21: 477 | J21: 716 | K21: 1 | M21: 女性 | N21: 148 | O21: 14 | P21: 44944 | Q21: モニカ | S21: =IFERROR(__xludf.DUMMYFUNCTION("""COMPUTED_VALUE"""),"ブエル") -> ブエル | T21: 女性 | U21: 148 | V21: 14 | W21: 44944 | X21: モニカ | Z21: 水
A22: 祖11 | B22: グシオンB | C22: イベント | D22: バースト | E22: スナイパー | F22: 5 | G22: 8586 | H22: 1037 | I22: 430 | J22: 491 | K22: 1 | M22: 女性 | N22: 140 | O22: 12 | P22: 45173 | Q22: アネット | S22: =IFERROR(__xludf.DUMMYFUNCTION("""COMPUTED_VALUE"""),"グシオン") -> グシオン | T22: 女性 | U22: 140 | V22: 12 | W22: 45173 | X22: アネット | Z22: 雷
A23: 祖11 | B23: グシオン | C23: 召喚 | D23: カウンター | E23: スナイパー | F23: 4 | G23: 7727 | H23: 857 | I23: 430 | J23: 697 | K23: 1 | M23: 女性 | N23: 140 | O23: 12 | P23: 45173 | Q23: アネット | S23: =IFERROR(__xludf.DUMMYFUNCTION("""COMPUTED_VALUE"""),"グシオン") -> グシオン | T23: 女性 | U23: 140 | V23: 12 | W23: 45173 | X23: アネット | Z23: 雷
A24: 祖12 | B24: シトリーR | C24: イベント | D24: ラッシュ | E24: トルーパー | F24: 2 | G24: 8547 | H24: 1001 | I24: 487 | J24: 421 | K24: 1 | M24: 女性 | N24: 165 | O24: 不明 | P24: 44966 | Q24: （忘却） | S24: =IFERROR(__xludf.DUMMYFUNCTION("""COMPUTED_VALUE"""),"シトリー") -> シトリー | T24: 女性 | U24: 165 | V24: 不明 | W24: 44966 | X24: （忘却） | Z24: 水
A25: 祖12 | B25: シトリー | C25: 召喚 | D25: カウンター | E25: トルーパー | F25: 5 | G25: 5667 | H25: 1176 | I25: 494 | J25: 476 | K25: 2 | M25: 女性 | N25: 165 | O25: 不明 | P25: 44966 | Q25: （忘却） | S25: =IFERROR(__xludf.DUMMYFUNCTION("""COMPUTED_VALUE"""),"シトリー") -> シトリー | T25: 女性 | U25: 165 | V25: 不明 | W25: 44966 | X25: （忘却） | Z25: 雷
A26: 祖13 | B26: ベレトB | C26: 召喚 | D26: バースト | E26: トルーパー | F26: 5 | G26: 7097 | H26: 1354 | I26: 407 | J26: 470 | K26: 1 | M26: 女性 | N26: 147 | O26: 15 | P26: 44948 | Q26: ？ | S26: =IFERROR(__xludf.DUMMYFUNCTION("""COMPUTED_VALUE"""),"ベレト") -> ベレト | T26: 女性 | U26: 147 | V26: 15 | W26: 44948 | X26: ？ | Z26: 氷
A27: 祖13 | B27: ベレト | C27: メイン | D27: カウンター | E27: トルーパー | F27: 5 | G27: 5968 | H27: 1206 | I27: 411 | J27: 626 | K27: 1 | M27: 女性 | N27: 147 | O27: 15 | P27: 44948 | Q27: ？ | S27: =IFERROR(__xludf.DUMMYFUNCTION("""COMPUTED_VALUE"""),"ベレト") -> ベレト | T27: 女性 | U27: 147 | V27: 15 | W27: 44948 | X27: ？ | Z27: 氷
A28: 祖14 | B28: レラジェR | C28: イベント | D28: ラッシュ | E28: スナイパー | F28: 2 | G28: 6116 | H28: 1210 | I28: 644 | J28: 430 | K28: 1 | M28: 女性 | N28: 161 | O28: 18 | P28: 45029 | Q28: （本名） | S28: =IFERROR(__xludf.DUMMYFUNCTION("""COMPUTED_VALUE"""),"レラジェ") -> レラジェ | T28: 女性 | U28: 161 | V28: 18 | W28: 45029 | X28: （本名） | Z28: 風
A29: 祖14 | B29: レラジェ | C29: 召喚 | D29: カウンター | E29: スナイパー | F29: 3 | G29: 5980 | H29: 1386 | I29: 424 | J29: 475 | K29: 1 | M29: 女性 | N29: 161 | O29: 18 | P29: 45029 | Q29: （本名） | S29: =IFERROR(__xludf.DUMMYFUNCTION("""COMPUTED_VALUE"""),"レラジェ") -> レラジェ | T29: 女性 | U29: 161 | V29: 18 | W29: 45029 | X29: （本名） | Z29: 風
A30: 祖15 | B30: エリゴスB | C30: 召喚 | D30: バースト | E30: ファイター | F30: 6 | G30: 7119 | H30: 1280 | I30: 410 | J30: 462 | K30: 2 | M30: 女性 | N30: 163 | O30: 25 | P30: 45055 | Q30: ？ | S30: =IFERROR(__xludf.DUMMYFUNCTION("""COMPUTED_VALUE"""),"エリゴス") -> エリゴス | T30: 女性 | U30: 163 | V30: 25 | W30: 45055 | X30: ？ | Z30: 火
A31: 祖15 | B31: エリゴス | C31: 召喚 | D31: ラッシュ | E31: ファイター | F31: 2 | G31: 5896 | H31: 768 | I31: 622 | J31: 627 | K31: 2 | M31: 女性 | N31: 163 | O31: 25 | P31: 45055 | Q31: ？ | S31: =IFERROR(__xludf.DUMMYFUNCTION("""COMPUTED_VALUE"""),"エリゴス") -> エリゴス | T31: 女性 | U31: 163 | V31: 25 | W31: 45055 | X31: ？ | Z31: 雷
A32: 祖16 | B32: ゼパルC | C32: 召喚 | D32: カウンター | E32: ファイター | F32: 4 | G32: 6210 | H32: 1150 | I32: 409 | J32: 642 | K32: 1 | M32: 女性 | N32: 153 | O32: 15 | P32: 45052 | Q32: アンナ | S32: =IFERROR(__xludf.DUMMYFUNCTION("""COMPUTED_VALUE"""),"ゼパル") -> ゼパル | T32: 女性 | U32: 153 | V32: 15 | W32: 45052 | X32: アンナ | Z32: 火
A33: 祖16 | B33: ゼパル | C33: 召喚 | D33: ラッシュ | E33: ファイター | F33: 2 | G33: 6210 | H33: 1209 | I33: 271 | J33: 693 | K33: 1 | M33: 女性 | N33: 153 | O33: 15 | P33: 45052 | Q33: アンナ | S33: =IFERROR(__xludf.DUMMYFUNCTION("""COMPUTED_VALUE"""),"ゼパル") -> ゼパル | T33: 女性 | U33: 153 | V33: 15 | W33: 45052 | X33: アンナ | Z33: 火
A34: 祖17 | B34: ボティスR | C34: イベント | D34: ラッシュ | E34: トルーパー | F34: 2 | G34: 6545 | H34: 1070 | I34: 505 | J34: 500 | K34: 1 | M34: 女性 | N34: 167 | O34: 24 | P34: 45280 | Q34: ？ | S34: =IFERROR(__xludf.DUMMYFUNCTION("""COMPUTED_VALUE"""),"ボティス") -> ボティス | T34: 女性 | U34: 167 | V34: 24 | W34: 45280 | X34: ？ | Z34: 雷
A35: 祖17 | B35: ボティス | C35: 召喚 | D35: カウンター | E35: トルーパー | F35: 4 | G35: 8845 | H35: 761 | I35: 717 | J35: 286 | K35: 1 | M35: 女性 | N35: 167 | O35: 24 | P35: 45280 | Q35: ？ | S35: =IFERROR(__xludf.DUMMYFUNCTION("""COMPUTED_VALUE"""),"ボティス") -> ボティス | T35: 女性 | U35: 167 | V35: 24 | W35: 45280 | X35: ？ | Z35: 雷
A36: 祖18 | B36: バティンB | C36: 召喚 | D36: バースト | E36: トルーパー | F36: 5 | G36: 7379 | H36: 1362 | I36: 419 | J36: 431 | K36: 1 | M36: 女性 | N36: 163 | O36: 23 | P36: 44935 | Q36: ？ | S36: =IFERROR(__xludf.DUMMYFUNCTION("""COMPUTED_VALUE"""),"バティン") -> バティン | T36: 女性 | U36: 163 | V36: 23 | W36: 44935 | X36: ？ | Z36: 火
A37: 祖18 | B37: バティン | C37: 召喚 | D37: ラッシュ | E37: トルーパー | F37: 3 | G37: 9140 | H37: 1222 | I37: 431 | J37: 423 | K37: 1 | M37: 女性 | N37: 163 | O37: 23 | P37: 44935 | Q37: ？ | S37: =IFERROR(__xludf.DUMMYFUNCTION("""COMPUTED_VALUE"""),"バティン") -> バティン | T37: 女性 | U37: 163 | V37: 23 | W37: 44935 | X37: ？ | Z37: 火
A38: 祖19 | B38: サレオスC | C38: 召喚 | D38: カウンター | E38: ファイター | F38: 4 | G38: 8330 | H38: 881 | I38: 525 | J38: 479 | K38: 1 | M38: 男性 | N38: 165 | O38: 25 | P38: 45116 | Q38: ？ | S38: =IFERROR(__xludf.DUMMYFUNCTION("""COMPUTED_VALUE"""),"サレオス") -> サレオス | T38: 男性 | U38: 165 | V38: 25 | W38: 45116 | X38: ？ | Z38: 水
A39: 祖19 | B39: サレオス | C39: 召喚 | D39: バースト | E39: ファイター | F39: 4 | G39: 8474 | H39: 945 | I39: 490 | J39: 424 | K39: 1 | M39: 男性 | N39: 165 | O39: 25 | P39: 45116 | Q39: ？ | S39: =IFERROR(__xludf.DUMMYFUNCTION("""COMPUTED_VALUE"""),"サレオス") -> サレオス | T39: 男性 | U39: 165 | V39: 25 | W39: 45116 | X39: ？ | Z39: 水
A40: 祖20 | B40: プルソンB | C40: メイン | D40: バースト | E40: トルーパー | F40: 4 | G40: 7094 | H40: 1225 | I40: 514 | J40: 392 | K40: 1 | M40: 男性 | N40: 166 | O40: 16 | P40: 45039 | Q40: エルデ | S40: =IFERROR(__xludf.DUMMYFUNCTION("""COMPUTED_VALUE"""),"プルソン") -> プルソン | T40: 男性 | U40: 166 | V40: 16 | W40: 45039 | X40: エルデ | Z40: 地
...

Sheet シート1
A1: 総数 | B1: 番号 | C1: 画像 | D1: 名前 | E1: 英語表記 | F1: 性別 | G1: 身長 | H1: 年齢 | I1: 誕生/転生日 | J1: 境遇 | K1: ヴィータ名 | L1: Re済 | M1: 専用衣装のテーマ | N1: 全高(cm) | O1: 体重(kg)
A2: 1 | B2: 祖01 | D2: バエル | E2: Bael | F2: 男性 | G2: 124 | H2: 不明 | I2: 44937 | J2: 転生 | K2: コラン | L2: 〇 | M2: ハロウィン | N2: 0.3～155 | O2: 0.07～72
A3: 2 | B3: 祖02 | D3: アガレス | E3: Agares | F3: 男性 | G3: 186 | H3: 26 | I3: 45106 | J3: 転生 | K3: 羽ばたく鰐 | L3: 〇 | M3: ミリタリー | N3: 527 | O3: 1750
A4: 3 | B4: 祖03 | D4: ウァサゴ | E4: Vassago | F4: 女性 | G4: 164 | H4: 19 | I4: 45021 | J4: 転生 | K4: エリザ | L4: 〇 | M4: イースター | N4: 416 | O4: 3640
A5: 4 | B5: 祖04 | D5: ガミジン | E5: Gamigin | F5: 男性 | G5: 185 | H5: 28 | I5: 45002 | J5: 転生 | K5: ？ | L5: 〇 | M5: フォーマル | N5: 566 | O5: 4820
A6: 5 | B6: 祖05 | D6: マルバス | E6: Marbas | F6: 女性 | G6: 145 | H6: 14 | I6: 45031 | J6: 転生 | K6: ？ | L6: 〇 | M6: ハロウィン | N6: 225 | O6: 96
A7: 6 | B7: 祖06 | D7: ウァレフォル | E7: Valefor | F7: 女性 | G7: 181 | H7: 25 | I7: 45005 | J7: 転生 | K7: ？ | L7: 〇 | M7: フォーマル | N7: 481 | O7: 2940
A8: 7 | B8: 祖07 | D8: アモン | E8: Amon | F8: 男性 | G8: 153 | H8: 13 | I8: 45157 | J8: 転生 | K8: リュカ | L8: 〇 | M8: 正月 | N8: 765 | O8: 3200
A9: 8 | B9: 祖08 | D9: バルバトス | E9: Barbatos | F9: 男性 | G9: 173 | H9: 不明 | I9: 45086 | J9: 転生 | K9: ？ | L9: 〇 | M9: 水着（色違い有） | N9: 712 | O9: 6580
A10: 9 | B10: 祖09 | D10: パイモン | E10: Paimon | F10: 男性 | G10: 179 | H10: 不明 | I10: 45188 | J10: 転生 | K10: ？ | L10: 〇 | M10: 1周年 | N10: 254 | O10: 125
A11: 10 | B11: 祖10 | D11: ブエル | E11: Buer | F11: 女性 | G11: 148 | H11: 14 | I11: 44944 | J11: 転生 | K11: モニカ | L11: 〇 | M11: 水着 | N11: 175 | O11: 43
A12: 11 | B12: 祖11 | D12: グシオン | E12: Gusion | F12: 女性 | G12: 140 | H12: 12 | I12: 45173 | J12: 転生 | K12: アネット | L12: 〇 | M12: フォーマル | N12: 383 | O12: 2130
A13: 12 | B13: 祖12 | D13: シトリー | E13: Sitri | F13: 女性 | G13: 165 | H13: 不明 | I13: 44966 | J13: 転生 | K13: （忘却） | L13: 〇 | M13: クリスマス | N13: 824 | O13: 5710
A14: 13 | B14: 祖13 | D14: ベレト | E14: Beleth | F14: 女性 | G14: 147 | H14: 15 | I14: 44948 | J14: 転生 | K14: ？ | L14: 〇 | M14: ハロウィン | N14: 811 | O14: 2120
A15: 14 | B15: 祖14 | D15: レラジェ | E15: Lerajie | F15: 女性 | G15: 161 | H15: 18 | I15: 45029 | J15: 転生 | K15: （本名） | L15: 〇 | M15: 部活 | N15: 232 | O15: 253
A16: 15 | B16: 祖15 | D16: エリゴス | E16: Eligos | F16: 女性 | G16: 163 | H16: 25 | I16: 45055 | J16: 転生 | K16: ？ | L16: 〇 | M16: バレンタイン | N16: 618 | O16: 4160
A17: 16 | B17: 祖16 | D17: ゼパル | E17: Zepar | F17: 女性 | G17: 153 | H17: 15 | I17: 45052 | J17: 転生 | K17: アンナ | L17: 〇 | M17: ハロウィン | N17: 313 | O17: 923
A18: 17 | B18: 祖17 | D18: ボティス | E18: Botis | F18: 女性 | G18: 167 | H18: 24 | I18: 45280 | J18: 転生 | K18: ？ | L18: 〇 | M18: 普段着 | N18: 467 | O18: 2630
A19: 18 | B19: 祖18 | D19: バティン | E19: Bathin | F19: 女性 | G19: 163 | H19: 23 | I19: 44935 | J19: 転生 | K19: ？ | L19: 〇 | M19: ネオヴィクトリアン | N19: 644 | O19: 104
A20: 19 | B20: 祖19 | D20: サレオス | E20: Saleos | F20: 男性 | G20: 165 | H20: 25 | I20: 45116 | J20: 転生 | K20: ？ | L20: 〇 | M20: セーラー | N20: 984(全長) | O20: 9920
A21: 20 | B21: 祖20 | D21: プルソン | E21: Purson | F21: 男性 | G21: 166 | H21: 16 | I21: 45039 | J21: 転生 | K21: エルデ | L21: 〇 | M21: 72ヶ月（6周年） | N21: 1488 | O21: 42600
A22: 21 | B22: 祖21 | D22: モラクス | E22: Morax | F22: 男性 | G22: 151 | H22: 15 | I22: 45178 | J22: 転生 | K22: （本名） | L22: 〇 | M22: 水着（色違い有） | N22: 666 | O22: 4510
A23: 22 | B23: 祖22 | D23: イポス | E23: Ipos | F23: 男性 | G23: 187 | H23: 37 | I23: 45287 | J23: 転生 | K23: ？ | L23: 〇 | M23: 水着 | N23: 559 | O23: 3810
A24: 23 | B24: 祖23 | D24: アイム | E24: Aim | F24: 女性 | G24: 160 | H24: 不明 | I24: 45088 | J24: 転生 | K24: ？ | L24: 〇 | M24: 浴衣 | N24: 238 | O24: 536
A25: 24 | B25: 祖24 | D25: ナベリウス | E25: Naberius | F25: 女性 | G25: 162 | H25: 20 | I25: 45044 | J25: 転生 | K25: ？ | L25: 〇 | M25: 正月 | N25: 493 | O25: 3300
A26: 25 | B26: 祖25 | D26: グラシャラボラス | E26: Glasya-Labolas | F26: 男性 | G26: 182 | H26: 24 | I26: 45057 | J26: 転生 | K26: ？ | L26: 〇 | M26: 学生服 | N26: 182 | O26: 2220
A27: 26 | B27: 祖26 | D27: ブネ | E27: Bune | F27: 男性 | G27: 195 | H27: 41 | I27: 45259 | J27: 転生 | K27: フガ | L27: 〇 | M27: 水着（色違い有） | N27: 1241 | O27: 26600
A28: 27 | B28: 祖27 | D28: ロノウェ | E28: Ronove | F28: 男性 | G28: 170 | H28: 18 | I28: 45265 | J28: 転生 | K28: ？ | L28: 〇 | M28: 応援団 | N28: 360 | O28: 1370
A29: 28 | B29: 祖28 | D29: ベリト | E29: Berith | F29: 男性 | G29: 180 | H29: 不明 | I29: 44996 | J29: 転生 | K29: ボルフ | L29: 〇 | M29: 浴衣 | N29: 588 | O29: 3570
A30: 29 | B30: 祖29 | D30: アスタロト | E30: Astaroth | F30: 女性 | G30: 170 | H30: 21 | I30: 45204 | J30: 転生 | K30: ？ | L30: 〇 | M30: クリスマス | N30: 1711(全長) | O30: 34300
A31: 30 | B31: 祖30 | D31: フォルネウス | E31: Forneus | F31: 男性 | G31: 178 | H31: 25 | I31: 44955 | J31: 転生 | K31: フォルス | L31: 〇 | M31: クリスマス | N31: 2331(全長) | O31: 12600
A32: 31 | B32: 祖31 | D32: フォラス | E32: Foras | F32: 男性 | G32: 176 | H32: 36 | I32: 45209 | J32: 転生 | K32: ？ | L32: 〇 | M32: クリスマス | N32: 904 | O32: 7810
A33: 32 | B33: 祖32 | D33: アスモデウス | E33: Asmodeus | F33: 女性 | G33: 186 | H33: 不明 | I33: 45248 | J33: 転生 | K33: ？ | L33: 〇 | M33: 1周年 | N33: 1207 | O33: 0
A34: 33 | B34: 祖33 | D34: ガープ | E34: Gaap | F34: 男性 | G34: 178 | H34: 22 | I34: 45267 | J34: 転生 | K34: セクトル | L34: 〇 | M34: 水着（色違い有） | N34: 1378 | O34: 30900
A35: 34 | B35: 祖34 | D35: フルフル | E35: Furfur | F35: 女性 | G35: 152 | H35: 不明 | I35: 44966 | J35: 転生 | K35: ？ | L35: 〇 | M35: パジャマ | N35: 836 | O35: 4360
A36: 35 | B36: 祖35 | D36: マルコシアス | E36: Marchosias | F36: 女性 | G36: 160 | H36: 23 | I36: 45083 | J36: 転生 | K36: ？ | L36: 〇 | M36: 水着（色違い有） | N36: 632 | O36: 3890
A37: 36 | B37: 祖36 | D37: ストラス | E37: Stolas | F37: 女性 | G37: 166 | H37: 16 | I37: 45097 | J37: 転生 | K37: ？ | L37: 〇 | M37: 学生服 | N37: 352 | O37: 156
A38: 37 | B38: 祖37 | D38: フェニックス | E38: Phoenix | F38: 男性 | G38: 174 | H38: 18 | I38: 45241 | J38: 転生 | K38: ルイゼット | L38: 〇 | M38: ホワイトデー | N38: 743 | O38: 133
A39: 38 | B39: 祖38 | D39: ハルファス | E39: Halphas | F39: 女性 | G39: 144 | H39: 15 | I39: 45064 | J39: 転生 | K39: アリン | L39: 〇 | M39: 正月 | N39: 144 | O39: 127
A40: 39 | B40: 祖39 | D40: マルファス | E40: Malphas | F40: 男性 | G40: 163 | H40: 17 | I40: 44991 | J40: 転生 | K40: ？ | L40: 〇 | M40: 水着 | N40: 1629 | O40: 38800
...

Sheet シート3
A1: バエル | B1: バースト | C1: スナイパー | D1: ストーリー | E1: 雷
A2: バエルC | B2: カウンター | C2: スナイパー | D2: 召喚 | E2: 雷
A3: アガレス | B3: バースト | C3: スナイパー | D3: 引き直し対象 | E3: 地
A4: アガレスC | B4: カウンター | C4: スナイパー | D4: 常設イベント | E4: 地
A5: ウァサゴ | B5: ラッシュ | C5: ファイター | D5: 引き直し対象 | E5: 地
A6: ウァサゴB | B6: バースト | C6: ファイター | D6: 召喚 | E6: 地
A7: ガミジン | B7: カウンター | C7: ファイター | D7: 引き直し対象 | E7: 地
A8: ガミジンB | B8: バースト | C8: ファイター | D8: イベント | E8: 地
A9: マルバス | B9: カウンター | C9: スナイパー | D9: 引き直し対象 | E9: 地
A10: マルバスR | B10: ラッシュ | C10: スナイパー | D10: 常設イベント | E10: 地
A11: ウァレフォル | B11: ラッシュ | C11: ファイター | D11: 引き直し対象 | E11: 地
A12: ウァレフォルC | B12: カウンター | C12: ファイター | D12: 召喚 | E12: 雷
... A273: アンダカ | B273: カウンター | C273: トルーパー | D273: 召喚 | E273: 風
